<?xml version="1.0"?>
<robot name="vgc10_gripper" xmlns:xacro="http://www.ros.org/wiki/xacro">

  <xacro:macro name="vgc10_gripper" params="prefix parent *origin">

    <!--CONTAINER -->
    <joint name="${prefix}_base_joint" type="fixed">
	    <xacro:insert_block name="origin"/>
      <parent link="${parent}"/>
      <child link="${prefix}_base_link"/>
    </joint>

    <link name="${prefix}_base_link">
	    <inertial>
	      <mass value="0.25"/>
	      <origin rpy="0 0 0" xyz="0 0 0"/>
	      <inertia ixx="0.001666" ixy="0" ixz="0" iyy="0.0041666" iyz="0" izz="0.0041666"/>
	    </inertial>
	    <visual>
	      <origin rpy="0 0 0" xyz="0 0 0"/>
	      <material name="alu_color">
           <color rgba="0.5 0.5 0.5 1"/>
        </material>
	      <geometry>
	        <mesh filename="package://vgc10_gripper_description/meshes/vgc10.stl"/>
	      </geometry>
	    </visual>
	    <collision>
	      <origin rpy="0 0 0" xyz="0.0 0 0"/>
	      <geometry>
          <!--box size="0.12 0.1 0.1" /-->
	        <mesh filename="package://vgc10_gripper_description/meshes/vgc10.dae"/>
	      </geometry>
	    </collision>
	  </link>

    <joint name="${prefix}_vacuum_joint" type="prismatic">
      <parent link="${prefix}_base_link"/>
      <child link="${prefix}_vacuum_link" />
      <origin xyz="0.1042 0 0" rpy="0 0 0" />
      <limit effort="1000" lower="0.0" upper="0.001" velocity="0.088"/>
      <axis xyz="1 0 0" /> 
    </joint>

    <link name="${prefix}_vacuum_link">
        <inertial>
          <mass value="0.01" />
          <origin xyz="0 0 0" />
          <inertia  ixx="1.0" ixy="0.0"  ixz="0.0"  iyy="1.0"  iyz="0.0"  izz="1.0" />
      </inertial>
    </link>

    <joint name="${prefix}_vacuum_cup_1_joint" type="revolute">
      <origin xyz="0.028 -0.0065 -0.0189" rpy="0 0 0"/>
      <parent link="${prefix}_vacuum_link"/>
      <child link="${prefix}_vacuum_cup_1_link"/>
      <axis xyz="1 0 0" rpy="0 0 0" />
      <limit effort="30" velocity="1.0" lower="-0.1" upper="0.1" />
    </joint>

    <link name="${prefix}_vacuum_cup_1_link">
      <inertial>
        <origin xyz="0 0 0" rpy="0 0 0"/>
        <mass value="0.01"/>
        <inertia ixx="0.000001"  ixy="0"  ixz="0" iyy="0.000001" iyz="0" izz="0.000001" />
      </inertial>
    </link>

    <joint name="${prefix}_vacuum_cup_2_joint" type="revolute">
      <origin xyz="0.028 -0.0065 0.0189" rpy="0 0 0"/>
      <parent link="${prefix}_vacuum_link"/>
      <child link="${prefix}_vacuum_cup_2_link"/>
      <axis xyz="1 0 0" rpy="0 0 0" />
      <limit effort="30" velocity="1.0" lower="-0.1" upper="0.1" />
    </joint>

    <link name="${prefix}_vacuum_cup_2_link">
      <inertial>
        <origin xyz="0 0 0" rpy="0 0 0"/>
        <mass value="0.01"/>
        <inertia ixx="0.000001"  ixy="0"  ixz="0" iyy="0.000001" iyz="0" izz="0.000001" />
      </inertial>
    </link>

    <joint name="${prefix}_vacuum_cup_3_joint" type="revolute">
      <origin xyz="0.028 0.02 0" rpy="0 0 0"/>
      <parent link="${prefix}_vacuum_link"/>
      <child link="${prefix}_vacuum_cup_3_link"/>
      <limit effort="30" velocity="1.0" lower="-0.1" upper="0.1" />
      <axis xyz="1 0 0" rpy="0 0 0" />
    </joint>

    <link name="${prefix}_vacuum_cup_3_link">
      <inertial>
        <origin xyz="0 0 0" rpy="0 0 0"/>
        <mass value="0.01"/>
        <inertia ixx="0.000001"  ixy="0"  ixz="0" iyy="0.000001" iyz="0" izz="0.000001" />
      </inertial>
    </link>

    <joint name="${prefix}_vacuum_cup_4_joint" type="revolute">
      <origin xyz="0.028 0 0" rpy="0 0 0"/>
      <parent link="${prefix}_vacuum_link"/>
      <child link="${prefix}_vacuum_cup_4_link"/>
      <limit effort="30" velocity="1.0" lower="-0.1" upper="0.1" />
      <axis xyz="1 0 0" rpy="0 0 0" />
    </joint>

    <link name="${prefix}_vacuum_cup_4_link">
      <inertial>
        <origin xyz="0 0 0" rpy="0 0 0"/>
        <mass value="0.01"/>
        <inertia ixx="0.000001"  ixy="0"  ixz="0" iyy="0.000001" iyz="0" izz="0.000001" />
      </inertial>
    </link>

    <!-- Transmission -->
    <transmission name="${prefix}_vacuum_transmission"  type="SimpleTransmission">
      <type>transmission_interface/SimpleTransmission</type>
      <actuator name="${prefix}_vacuum_joint_motor">
          <mechanicalReduction>1</mechanicalReduction>
      </actuator>
      <joint name="${prefix}_vacuum_joint">
          <hardwareInterface>hardware_interface/PositionJointInterface</hardwareInterface>
      </joint>
    </transmission>

    <transmission name="${prefix}_vacuum_cup_1_joint_transmission">
      <type>transmission_interface/SimpleTransmission</type>
      <joint name="${prefix}_vacuum_cup_1_joint">
        <hardwareInterface>hardware_interface/PositionJointInterface</hardwareInterface>
      </joint>
      <actuator name="${prefix}_vacuum_cup_1_joint_motor">
        <hardwareInterface>hardware_interface/PositionActuatorInterface</hardwareInterface>
        <mechanicalReduction>1</mechanicalReduction>
      </actuator>
    </transmission>

    <transmission name="${prefix}_vacuum_cup_2_joint_transmission">
      <type>transmission_interface/SimpleTransmission</type>
      <joint name="${prefix}_vacuum_cup_2_joint">
        <hardwareInterface>hardware_interface/PositionJointInterface</hardwareInterface>
      </joint>
      <actuator name="${prefix}_vacuum_cup_2_joint_motor">
        <hardwareInterface>hardware_interface/PositionActuatorInterface</hardwareInterface>
        <mechanicalReduction>1</mechanicalReduction>
      </actuator>
    </transmission>

    <transmission name="${prefix}_vacuum_cup_3_joint_transmission">
      <type>transmission_interface/SimpleTransmission</type>
      <joint name="${prefix}_vacuum_cup_3_joint">
        <hardwareInterface>hardware_interface/PositionJointInterface</hardwareInterface>
      </joint>
      <actuator name="${prefix}_vacuum_cup_3_joint_motor">
        <hardwareInterface>hardware_interface/PositionActuatorInterface</hardwareInterface>
        <mechanicalReduction>1</mechanicalReduction>
      </actuator>
    </transmission>

    <transmission name="${prefix}_vacuum_cup_4_joint_transmission">
      <type>transmission_interface/SimpleTransmission</type>
      <joint name="${prefix}_vacuum_cup_4_joint">
        <hardwareInterface>hardware_interface/PositionJointInterface</hardwareInterface>
      </joint>
      <actuator name="${prefix}_vacuum_cup_4_joint_motor">
        <hardwareInterface>hardware_interface/PositionActuatorInterface</hardwareInterface>
        <mechanicalReduction>1</mechanicalReduction>
      </actuator>
    </transmission>

  </xacro:macro>

</robot>